<?xml version="1.0" encoding="UTF-8"?>
<testsuite name="scp.targets.vertx.InitiatorExecutorTest" tests="8" skipped="0" failures="0" errors="0" timestamp="2015-11-30T21:45:00" hostname="DESKTOP-PE2SLM5" time="0.845">
  <properties/>
  <testcase name="testActionFailed" classname="scp.targets.vertx.InitiatorExecutorTest" time="0.063"/>
  <testcase name="testExcessLoad" classname="scp.targets.vertx.InitiatorExecutorTest" time="0.203"/>
  <testcase name="testRemoteUnknownFailure" classname="scp.targets.vertx.InitiatorExecutorTest" time="0.11"/>
  <testcase name="testActionUnavailable" classname="scp.targets.vertx.InitiatorExecutorTest" time="0.11"/>
  <testcase name="testLocalTimeOut" classname="scp.targets.vertx.InitiatorExecutorTest" time="0.015"/>
  <testcase name="testFastInitiation" classname="scp.targets.vertx.InitiatorExecutorTest" time="0.094"/>
  <testcase name="testActionSucceeded" classname="scp.targets.vertx.InitiatorExecutorTest" time="0.11"/>
  <testcase name="testRemoteTimeOut" classname="scp.targets.vertx.InitiatorExecutorTest" time="0.125"/>
  <system-out><![CDATA[]]></system-out>
  <system-err><![CDATA[[vert.x-eventloop-thread-0] WARN scp.impl.ExecutorInvoker - Dropping 2-th request
[vert.x-eventloop-thread-3] ERROR scp.impl.ExecutorInvoker - Failed to handle 1-th request
java.util.concurrent.ExecutionException: java.lang.RuntimeException: Don't Panic! This exception is good :)
	at java.util.concurrent.FutureTask.report(FutureTask.java:122)
	at java.util.concurrent.FutureTask.get(FutureTask.java:206)
	at scp.impl.ExecutorInvoker.invokeHandler(ExecutorInvoker.java:103)
	at scp.impl.ExecutorInvoker.execute(ExecutorInvoker.java:90)
	at scp.targets.vertx.CommunicationManagerImpl.lambda$registerExecutor$24(CommunicationManagerImpl.java:255)
	at org.vertx.java.core.eventbus.impl.DefaultEventBus$11.run(DefaultEventBus.java:951)
	at org.vertx.java.core.impl.DefaultContext$3.run(DefaultContext.java:175)
	at io.netty.util.concurrent.SingleThreadEventExecutor.runAllTasks(SingleThreadEventExecutor.java:370)
	at io.netty.channel.nio.NioEventLoop.run(NioEventLoop.java:357)
	at io.netty.util.concurrent.SingleThreadEventExecutor$2.run(SingleThreadEventExecutor.java:116)
	at java.lang.Thread.run(Thread.java:745)
Caused by: java.lang.RuntimeException: Don't Panic! This exception is good :)
	at scp.api.InitiatorExecutorTest$4.execute(InitiatorExecutorTest.java:161)
	at scp.api.InitiatorExecutorTest$4.execute(InitiatorExecutorTest.java:158)
	at scp.impl.ExecutorInvoker.lambda$invokeHandler$0(ExecutorInvoker.java:100)
	at java.util.concurrent.FutureTask.run(FutureTask.java:266)
	at java.util.concurrent.ThreadPoolExecutor.runWorker(ThreadPoolExecutor.java:1142)
	at java.util.concurrent.ThreadPoolExecutor$Worker.run(ThreadPoolExecutor.java:617)
	... 1 more
[Test worker] WARN scp.impl.InitiateRequester - Timed out handling 1-th initiation
[Test worker] WARN scp.impl.InitiateRequester - Dropping 2-th initiation
[vert.x-eventloop-thread-3] WARN scp.impl.ExecutorInvoker - Timed out handling 1-th request
]]></system-err>
</testsuite>
