<?xml version="1.0" encoding="UTF-8"?>
<testsuite name="scp.targets.dds.InitiatorExecutorTest" tests="8" skipped="1" failures="0" errors="0" timestamp="2015-11-30T21:43:13" hostname="DESKTOP-PE2SLM5" time="23.544">
  <properties/>
  <testcase name="testActionFailed" classname="scp.targets.dds.InitiatorExecutorTest" time="2.483"/>
  <testcase name="testExcessLoad" classname="scp.targets.dds.InitiatorExecutorTest" time="3.437"/>
  <testcase name="testRemoteUnknownFailure" classname="scp.targets.dds.InitiatorExecutorTest" time="2.407"/>
  <testcase name="testActionUnavailable" classname="scp.targets.dds.InitiatorExecutorTest" time="3.437"/>
  <testcase name="testLocalTimeOut" classname="scp.targets.dds.InitiatorExecutorTest" time="3.406">
    <skipped/>
  </testcase>
  <testcase name="testFastInitiation" classname="scp.targets.dds.InitiatorExecutorTest" time="2.407"/>
  <testcase name="testActionSucceeded" classname="scp.targets.dds.InitiatorExecutorTest" time="2.406"/>
  <testcase name="testRemoteTimeOut" classname="scp.targets.dds.InitiatorExecutorTest" time="3.561"/>
  <system-out><![CDATA[Exception was thrown while processing request
]]></system-out>
  <system-err><![CDATA[com.rti.dds.infrastructure.RETCODE_BAD_PARAMETER: Invalid related request identity (sequence number is SequenceNumber_t[high=-1, low=4294967295]
	at com.rti.connext.requestreply.Replier.getWriteParamsForRelatedRequest(Unknown Source)
	at com.rti.connext.requestreply.Replier.sendReply(Unknown Source)
	at com.rti.connext.requestreply.SimpleReplier$ReplierListenerAdapter.onRequestAvailable(Unknown Source)
	at com.rti.connext.requestreply.Replier$ReplierDataReaderListener.on_data_available(Unknown Source)
	at com.rti.dds.subscription.DataReaderListenerImpl.on_data_available(Unknown Source)
[Thread-72] WARN scp.impl.ExecutorInvoker - Dropping 2-th request
[Thread-78] ERROR scp.impl.ExecutorInvoker - Failed to handle 1-th request
java.util.concurrent.ExecutionException: java.lang.RuntimeException: Don't Panic! This exception is good :)
	at java.util.concurrent.FutureTask.report(FutureTask.java:122)
	at java.util.concurrent.FutureTask.get(FutureTask.java:206)
	at scp.impl.ExecutorInvoker.invokeHandler(ExecutorInvoker.java:103)
	at scp.impl.ExecutorInvoker.execute(ExecutorInvoker.java:90)
	at scp.targets.dds.CommunicationManagerImpl$3.invoke(CommunicationManagerImpl.java:304)
	at scp.targets.dds.CommunicationManagerImpl$3.invoke(CommunicationManagerImpl.java:300)
	at scp.targets.dds.RequestReplyBasedGeneralServerRequestHandler.onRequestAvailable(RequestReplyBasedGeneralServerRequestHandler.java:61)
	at scp.targets.dds.RequestReplyBasedGeneralServerRequestHandler.onRequestAvailable(RequestReplyBasedGeneralServerRequestHandler.java:27)
	at com.rti.connext.requestreply.SimpleReplier$ReplierListenerAdapter.onRequestAvailable(Unknown Source)
	at com.rti.connext.requestreply.Replier$ReplierDataReaderListener.on_data_available(Unknown Source)
	at com.rti.dds.subscription.DataReaderListenerImpl.on_data_available(Unknown Source)
Caused by: java.lang.RuntimeException: Don't Panic! This exception is good :)
	at scp.api.InitiatorExecutorTest$4.execute(InitiatorExecutorTest.java:161)
	at scp.api.InitiatorExecutorTest$4.execute(InitiatorExecutorTest.java:158)
	at scp.impl.ExecutorInvoker.lambda$invokeHandler$0(ExecutorInvoker.java:100)
	at java.util.concurrent.FutureTask.run(FutureTask.java:266)
	at java.util.concurrent.ThreadPoolExecutor.runWorker(ThreadPoolExecutor.java:1142)
	at java.util.concurrent.ThreadPoolExecutor$Worker.run(ThreadPoolExecutor.java:617)
	at java.lang.Thread.run(Thread.java:745)
[Test worker] WARN scp.impl.InitiateRequester - Dropping 2-th initiation
[Thread-115] WARN scp.impl.ExecutorInvoker - Timed out handling 1-th request
]]></system-err>
</testsuite>
