<?xml version="1.0" encoding="UTF-8"?>
<testsuite name="scp.targets.dds.RequesterResponderTest" tests="8" skipped="1" failures="0" errors="0" timestamp="2015-12-05T01:28:13" hostname="DESKTOP-PE2SLM5" time="25.468">
  <properties/>
  <testcase name="testExcessLoad" classname="scp.targets.dds.RequesterResponderTest" time="3.469"/>
  <testcase name="testRemoteUnknownFailure" classname="scp.targets.dds.RequesterResponderTest" time="3.437"/>
  <testcase name="testLocalTimeOut" classname="scp.targets.dds.RequesterResponderTest" time="3.421">
    <skipped/>
  </testcase>
  <testcase name="testStaleData" classname="scp.targets.dds.RequesterResponderTest" time="3.423"/>
  <testcase name="testDataUnavailable" classname="scp.targets.dds.RequesterResponderTest" time="2.422"/>
  <testcase name="testSuccessfulRequest" classname="scp.targets.dds.RequesterResponderTest" time="2.421"/>
  <testcase name="testFastRequest" classname="scp.targets.dds.RequesterResponderTest" time="3.422"/>
  <testcase name="testRemoteTimeOut" classname="scp.targets.dds.RequesterResponderTest" time="3.453"/>
  <system-out><![CDATA[]]></system-out>
  <system-err><![CDATA[[Thread-146] WARN scp.impl.ResponderInvoker - Dropping 2-th reception
[Thread-152] ERROR scp.impl.ResponderInvoker - Failed to handle 1-th reception
java.util.concurrent.ExecutionException: java.lang.RuntimeException: Don't Panic! This exception is good :)
	at java.util.concurrent.FutureTask.report(FutureTask.java:122)
	at java.util.concurrent.FutureTask.get(FutureTask.java:206)
	at scp.impl.ResponderInvoker.invokeHandler(ResponderInvoker.java:100)
	at scp.impl.ResponderInvoker.serviceRequest(ResponderInvoker.java:87)
	at scp.targets.dds.CommunicationManagerImpl$1.invoke(CommunicationManagerImpl.java:214)
	at scp.targets.dds.CommunicationManagerImpl$1.invoke(CommunicationManagerImpl.java:210)
	at scp.targets.dds.RequestReplyBasedGeneralServerRequestHandler.onRequestAvailable(RequestReplyBasedGeneralServerRequestHandler.java:61)
	at scp.targets.dds.RequestReplyBasedGeneralServerRequestHandler.onRequestAvailable(RequestReplyBasedGeneralServerRequestHandler.java:27)
	at com.rti.connext.requestreply.SimpleReplier$ReplierListenerAdapter.onRequestAvailable(Unknown Source)
	at com.rti.connext.requestreply.Replier$ReplierDataReaderListener.on_data_available(Unknown Source)
	at com.rti.dds.subscription.DataReaderListenerImpl.on_data_available(Unknown Source)
Caused by: java.lang.RuntimeException: Don't Panic! This exception is good :)
	at scp.api.RequesterResponderTest$3.respond(RequesterResponderTest.java:163)
	at java.util.concurrent.FutureTask.run(FutureTask.java:266)
	at java.util.concurrent.ThreadPoolExecutor.runWorker(ThreadPoolExecutor.java:1142)
	at java.util.concurrent.ThreadPoolExecutor$Worker.run(ThreadPoolExecutor.java:617)
	at java.lang.Thread.run(Thread.java:745)
[Test worker] INFO scp.impl.RequestRequester - Handling stale 1-th response
[Test worker] WARN scp.impl.RequestRequester - Dropping 2-th request
[Thread-193] WARN scp.impl.ResponderInvoker - Timed out handling 1-th reception
]]></system-err>
</testsuite>
